using LessonA.DayOne;
using System;
using System.Collections.Generic;
using System.Linq;
using System.Text;
using System.Threading.Tasks;

namespace LessonA.DayThree
{
    internal class ExceptionsDemo
    {
        public static void DemoAExceptions()
        {
            Console.WriteLine("\tEnter a no for X");
            int x = int.Parse(Console.ReadLine());
            Console.WriteLine("\tEnter a no Y");
            int y = int.Parse(Console.ReadLine());
            Calculator c1 = new Calculator();
            int z = c1.Divide(x, y);
            Console.WriteLine("Result in M3 " + z);
        }

        class Calculator
        {
            public int Divide(int x, int y)
            {
                return x / y;
            }
            public int Add(int x, int y)
            {
                return x + y;
            }
            public int Multiply(int x, int y)
            {
                return x * y;
            }
            public int Subtract(int x, int y)
            {
                return x - y;
            }

            public int DivideA(int x, int y)
            {
                //if (y == 0)
                //    throw new ZeroValueException();
               /* if (y == 0)
                    throw new ZeroValueException("ERROR!!! Value for Y is " + y);*/
                return x / y;
            }
        }

        public static void TestDivide()
        {
            Calculator c1 = null;
            int v1 = 0;
            int v2 = 0;
            int v3 = 0;
            try
            {
                Console.WriteLine("Enter a no X");
                v1 = int.Parse(Console.ReadLine());
                Console.WriteLine("Enter another no Y");
                v2 = int.Parse(Console.ReadLine());
                c1 = new Calculator();
                v3 = c1.Divide(v1, v2);
                Console.WriteLine("Result of {0}/{1}={2}", v1, v2, v3);
            }
            catch (Exception err)
            {
                Console.WriteLine("Error1 Type " + err.GetType().FullName);
                Console.WriteLine("Error1 Message " + err.Message);
                Console.WriteLine("Error1 SOURCE " + err.Source);
                Console.WriteLine("Error1 TargetSite " + err.TargetSite.Name);
            }
        }

        public static void TestCatchFinally()
        {
            Console.WriteLine("Before Try");
            int v1 = 0;
            // return;
            try
            {
                Console.WriteLine("Inside Try");
                Console.WriteLine("Enter a no");
                v1 = int.Parse(Console.ReadLine());
            }
            catch (Exception err)
            {
                Console.WriteLine("Inside Catch " + err.Message);
            }
            finally
            {
                Console.WriteLine("Inside  Finally");
            }
            Console.WriteLine("After  Finally");
        }
    }
}
